Workbook

Sheet COVER
B2: AutoPark — Financial Model
B3: Autonomous Self-Parking Platform | aUToronto Spinout | University of Toronto
B4: Seed Round Investment Model | March 2026
B6: MODEL OVERVIEW
B7: Purpose | C7: Two-phase startup financial model: Phase 1 loss-leader bridge product (2026–2028) + Phase 2 L4/L5 autonomous parking platform (2028+). Models seed round sizing, break-even, NPV, IRR, and OEM acquisition valuation.
B8: Terminal Event | C8: OEM acquisition (GM primary target). Terminal value modeled via three methods: ARR multiple, per-gate network value, strategic comparable (GM/Cruise).
B9: Scenarios | C9: Bear / Base / Bull across RSU rollout pace and transaction volume. $15 blended average ticket price (conservative).
B10: Seed Ask | C10: Modular: $500k / $1M / $2M. Model shows what each tranche buys in RSU gates, runway, and traction milestones.
B11: Time Horizon | C11: 2026 – 2032 (7 years). Monthly detail for Year 1–2 (J-Curve); annual thereafter.
B13: COLOR CODING LEGEND
B14: Blue text | C14: Hardcoded input — edit these to change scenarios
B15: Black text | C15: Formula — calculated automatically
B16: Green text | C16: Cross-sheet link — pulls from ASSUMPTIONS tab
B17: Yellow background | C17: Key assumption requiring attention
B18: Bear shading (pink) | C18: Bear case scenario values
B19: Base shading (green) | C19: Base case scenario values
B20: Bull shading (blue) | C20: Bull case scenario values
B22: TABLE OF CONTENTS
B23: ASSUMPTIONS | C23: All editable inputs: rollout, pricing, costs, Phase 2 assumptions, financial parameters
B24: P&L | C24: Annual Income Statement 2026–2032, Bear / Base / Bull scenarios
B25: CASH FLOW | C25: Monthly J-Curve: 24-month burn, break-even inflection, seed runway
B26: UNIT ECONOMICS | C26: Per-RSU payback, LTV/CAC, platform-level metrics
B27: NPV & SCENARIOS | C27: DCF, IRR, sensitivity table, scenario comparison dashboard
B28: EXIT VALUATION | C28: Three acquisition valuation methods + investor return waterfall

Sheet ASSUMPTIONS
A1: AutoPark — Model Assumptions
A2: All blue cells are editable inputs. Black = formulas. Yellow = key assumptions needing review.
A4: A. MARKET & PRICING ASSUMPTIONS
A5: Parameter | B5: Value | C5: Units | D5: Note
A6: Average Parking Ticket — Phase 1 (Bridge) | B6: 15 | C6: $/session | D6: Conservative blended downtown Toronto rate
A7: Average Parking Ticket — Phase 2 (L4/L5) | B7: 20 | C7: $/session | D7: AV premium lots charge more
A8: AutoPark Total Commission Rate | B8: 0.35 | C8: % | D8: 35% of base ticket; split dynamically between lot + user
A9: Stripe Transaction Rate | B9: 0.029 | C9: % | D9: Per Stripe standard API pricing
A10: Stripe Fixed Fee | B10: 0.3 | C10: $/txn | D10: Per Stripe standard API pricing
A11: Stripe Radar Fee | B11: 0.02 | C11: $/txn | D11: Automated fraud detection — required for unattended gates
A12: Free-Lot Convenience Fee | B12: 0.74 | C12: $/session | D12: Mid-range of $0.49–$0.99 flat fee
A13: Free-Lot Session Mix | B13: 0.12 | C13: % | D13: Est. 12% of sessions on free/metered lots
A14: Operating Days per Year | B14: 365 | C14: days | D14: 365-day operation
A15: Phase 1 End Year (Bridge → L4 transition) | B15: 2028 | C15: year | D15: L4/L5 commercial scale assumed 2028
A17: B. RSU ROLLOUT — NEW GATES ADDED PER YEAR
A18: Year | B18: Bear | C18: Base | D18: Bull | E18: Note
A19: 2026 | B19: 50 | C19: 100 | D19: 200 | E19: Pilot year — 3–5 signed LOIs; U of T + GreenP
A20: 2027 | B20: 100 | C20: 200 | D20: 400 | E20: Scale city-wide Toronto; first expansion city
A21: 2028 | B21: 75 | C21: 150 | D21: 300 | E21: Phase 2 transition year — slower hardware adds, focus on OBU OEM integration
A22: 2029 | B22: 50 | C22: 100 | D22: 200 | E22: Steady state growth — revenues accelerating
A23: 2030 | B23: 50 | C23: 100 | D23: 200 | E23: North America expansion begins
A24: 2031 | B24: 25 | C24: 75 | D24: 150 | E24: Mature network; focus on OEM SaaS ARR
A25: 2032 | B25: 25 | C25: 75 | D25: 150 | E25: Pre-acquisition scale
A27: C. TRANSACTIONS PER GATE PER DAY (GROWING WITH ADOPTION)
A28: Year | B28: Bear | C28: Base | D28: Bull | E28: Note
A29: 2026 | B29: 8 | C29: 15 | D29: 25 | E29: Early adoption — bridge product ramp
A30: 2027 | B30: 10 | C30: 18 | D30: 30 | E30: Growing user base + expanded lot network
A31: 2028 | B31: 12 | C31: 22 | D31: 35 | E31: Phase 2 early — first L4 vehicles + bridge still active
A32: 2029 | B32: 15 | C32: 25 | D32: 40 | E32: Phase 2 scaling — L4 fleet growing
A33: 2030 | B33: 15 | C33: 25 | D33: 40 | E33: Steady state
A34: 2031 | B34: 15 | C34: 25 | D34: 40 | E34: Steady state
A35: 2032 | B35: 15 | C35: 25 | D35: 40 | E35: Steady state
A37: D. HARDWARE COSTS
A38: Parameter | B38: Value | C38: Units | D38: Source
A39: RSU Unit Cost — Pilot Phase (<200 cumulative gates) | B39: 401 | C39: $/gate | D39: Gemini Deep Research validated BOM (CM4+AG15+RFID+enclosure)
A40: RSU Unit Cost — Scale Phase (≥200 cumulative gates) | B40: 235 | C40: $/gate | D40: Custom PCB production run; Gemini Deep Research validated
A41: RSU Pilot-to-Scale Threshold (cumulative gates) | B41: 200 | C41: gates | D41: Switch to scale pricing above this gate count
A42: OBU Unit Cost — Pilot (Cohda MK6C) | B42: 739 | C42: $/unit | D42: Gemini Deep Research validated BOM; pre-certified avoids FCC NRE
A43: OBU Unit Cost — Production (Snapdragon 2150) | B43: 204 | C43: $/unit | D43: Gemini Deep Research validated; custom PCB at 50k units
A44: RSU Subsidy Rate (% of cost charged to lot operator) | B44: 0 | C44: % | D44: Phase 1: 100% subsidised to acquire operators. Recovered via commissions.
...

Sheet P&L
A1: AutoPark — Income Statement (P&L) | 2026–2032
A2: Green text = cross-sheet formula from ASSUMPTIONS tab. Blue = hardcoded input. Black = formula.
C4: ◆ Bear Case | K4: ◆ Base Case | S4: ◆ Bull Case
A5: Year → | C5: 2026 | D5: 2027 | E5: 2028 | F5: 2029 | G5: 2030 | H5: 2031 | I5: 2032 | K5: 2026 | L5: 2027 | M5: 2028 | N5: 2029 | O5: 2030 | P5: 2031 | Q5: 2032 | S5: 2026 | T5: 2027 | U5: 2028 | V5: 2029 | W5: 2030 | X5: 2031 | Y5: 2032
A6: REVENUE
A7: Net Commission Revenue (35% − Stripe) | C7: =((ASSUMPTIONS!B19)*ASSUMPTIONS!B29*ASSUMPTIONS!B14*ASSUMPTIONS!B6*ASSUMPTIONS!B8)-((ASSUMPTIONS!B19)*ASSUMPTIONS!B29*ASSUMPTIONS!B14*(ASSUMPTIONS!B10+ASSUMPTIONS!B9*ASSUMPTIONS!B6*1.1+ASSUMPTIONS!B11)) -> 649919 | D7: =((ASSUMPTIONS!B19+ASSUMPTIONS!B20)*ASSUMPTIONS!B30*ASSUMPTIONS!B14*ASSUMPTIONS!B6*ASSUMPTIONS!B8)-((ASSUMPTIONS!B19+ASSUMPTIONS!B20)*ASSUMPTIONS!B30*ASSUMPTIONS!B14*(ASSUMPTIONS!B10+ASSUMPTIONS!B9*ASSUMPTIONS!B6*1.1+ASSUMPTIONS!B11)) -> 2437196.2 | E7: =((ASSUMPTIONS!B19+ASSUMPTIONS!B20+ASSUMPTIONS!B21)*ASSUMPTIONS!B31*ASSUMPTIONS!B14*ASSUMPTIONS!B7*ASSUMPTIONS!B8)-((ASSUMPTIONS!B19+ASSUMPTIONS!B20+ASSUMPTIONS!B21)*ASSUMPTIONS!B31*ASSUMPTIONS!B14*(ASSUMPTIONS!B10+ASSUMPTIONS!B9*ASSUMPTIONS!B7*1.1+ASSUMPTIONS!B11)) -> 5954391 | F7: =((ASSUMPTIONS!B19+ASSUMPTIONS!B20+ASSUMPTIONS!B21+ASSUMPTIONS!B22)*ASSUMPTIONS!B32*ASSUMPTIONS!B14*ASSUMPTIONS!B7*ASSUMPTIONS!B8)-((ASSUMPTIONS!B19+ASSUMPTIONS!B20+ASSUMPTIONS!B21+ASSUMPTIONS!B22)*ASSUMPTIONS!B32*ASSUMPTIONS!B14*(ASSUMPTIONS!B10+ASSUMPTIONS!B9*ASSUMPTIONS!B7*1.1+ASSUMPTIONS!B11)) -> 9096986.2 | G7: =((ASSUMPTIONS!B19+ASSUMPTIONS!B20+ASSUMPTIONS!B21+ASSUMPTIONS!B22+ASSUMPTIONS!B23)*ASSUMPTIONS!B33*ASSUMPTIONS!B14*ASSUMPTIONS!B7*ASSUMPTIONS!B8)-((ASSUMPTIONS!B19+ASSUMPTIONS!B20+ASSUMPTIONS!B21+ASSUMPTIONS!B22+ASSUMPTIONS!B23)*ASSUMPTIONS!B33*ASSUMPTIONS!B14*(ASSUMPTIONS!B10+ASSUMPTIONS!B9*ASSUMPTIONS!B7*1.1+ASSUMPTIONS!B11)) -> 10750984 | H7: =((ASSUMPTIONS!B19+ASSUMPTIONS!B20+ASSUMPTIONS!B21+ASSUMPTIONS!B22+ASSUMPTIONS!B23+ASSUMPTIONS!B24)*ASSUMPTIONS!B34*ASSUMPTIONS!B14*ASSUMPTIONS!B7*ASSUMPTIONS!B8)-((ASSUMPTIONS!B19+ASSUMPTIONS!B20+ASSUMPTIONS!B21+ASSUMPTIONS!B22+ASSUMPTIONS!B23+ASSUMPTIONS!B24)*ASSUMPTIONS!B34*ASSUMPTIONS!B14*(ASSUMPTIONS!B10+ASSUMPTIONS!B9*ASSUMPTIONS!B7*1.1+ASSUMPTIONS!B11)) -> 11577982 | I7: =((ASSUMPTIONS!B19+ASSUMPTIONS!B20+ASSUMPTIONS!B21+ASSUMPTIONS!B22+ASSUMPTIONS!B23+ASSUMPTIONS!B24+ASSUMPTIONS!B25)*ASSUMPTIONS!B35*ASSUMPTIONS!B14*ASSUMPTIONS!B7*ASSUMPTIONS!B8)-((ASSUMPTIONS!B19+ASSUMPTIONS!B20+ASSUMPTIONS!B21+ASSUMPTIONS!B22+ASSUMPTIONS!B23+ASSUMPTIONS!B24+ASSUMPTIONS!B25)*ASSUMPTIONS!B35*ASSUMPTIONS!B14*(ASSUMPTIONS!B10+ASSUMPTIONS!B9*ASSUMPTIONS!B7*1.1+ASSUMPTIONS!B11)) -> 12404981 | K7: =((ASSUMPTIONS!C19)*ASSUMPTIONS!C29*ASSUMPTIONS!B14*ASSUMPTIONS!B6*ASSUMPTIONS!B8)-((ASSUMPTIONS!C19)*ASSUMPTIONS!C29*ASSUMPTIONS!B14*(ASSUMPTIONS!B10+ASSUMPTIONS!B9*ASSUMPTIONS!B6*1.1+ASSUMPTIONS!B11)) -> 2437196.2 | L7: =((ASSUMPTIONS!C19+ASSUMPTIONS!C20)*ASSUMPTIONS!C30*ASSUMPTIONS!B14*ASSUMPTIONS!B6*ASSUMPTIONS!B8)-((ASSUMPTIONS!C19+ASSUMPTIONS!C20)*ASSUMPTIONS!C30*ASSUMPTIONS!B14*(ASSUMPTIONS!B10+ASSUMPTIONS!B9*ASSUMPTIONS!B6*1.1+ASSUMPTIONS!B11)) -> 8773906.5 | M7: =((ASSUMPTIONS!C19+ASSUMPTIONS!C20+ASSUMPTIONS!C21)*ASSUMPTIONS!C31*ASSUMPTIONS!B14*ASSUMPTIONS!B7*ASSUMPTIONS!B8)-((ASSUMPTIONS!C19+ASSUMPTIONS!C20+ASSUMPTIONS!C21)*ASSUMPTIONS!C31*ASSUMPTIONS!B14*(ASSUMPTIONS!B10+ASSUMPTIONS!B9*ASSUMPTIONS!B7*1.1+ASSUMPTIONS!B11)) -> 21832767 | N7: =((ASSUMPTIONS!C19+ASSUMPTIONS!C20+ASSUMPTIONS!C21+ASSUMPTIONS!C22)*ASSUMPTIONS!C32*ASSUMPTIONS!B14*ASSUMPTIONS!B7*ASSUMPTIONS!B8)-((ASSUMPTIONS!C19+ASSUMPTIONS!C20+ASSUMPTIONS!C21+ASSUMPTIONS!C22)*ASSUMPTIONS!C32*ASSUMPTIONS!B14*(ASSUMPTIONS!B10+ASSUMPTIONS!B9*ASSUMPTIONS!B7*1.1+ASSUMPTIONS!B11)) -> 30323288 | O7: =((ASSUMPTIONS!C19+ASSUMPTIONS!C20+ASSUMPTIONS!C21+ASSUMPTIONS!C22+ASSUMPTIONS!C23)*ASSUMPTIONS!C33*ASSUMPTIONS!B14*ASSUMPTIONS!B7*ASSUMPTIONS!B8)-((ASSUMPTIONS!C19+ASSUMPTIONS!C20+ASSUMPTIONS!C21+ASSUMPTIONS!C22+ASSUMPTIONS!C23)*ASSUMPTIONS!C33*ASSUMPTIONS!B14*(ASSUMPTIONS!B10+ASSUMPTIONS!B9*ASSUMPTIONS!B7*1.1+ASSUMPTIONS!B11)) -> 35836612 | P7: =((ASSUMPTIONS!C19+ASSUMPTIONS!C20+ASSUMPTIONS!C21+ASSUMPTIONS!C22+ASSUMPTIONS!C23+ASSUMPTIONS!C24)*ASSUMPTIONS!C34*ASSUMPTIONS!B14*ASSUMPTIONS!B7*ASSUMPTIONS!B8)-((ASSUMPTIONS!C19+ASSUMPTIONS!C20+ASSUMPTIONS!C21+ASSUMPTIONS!C22+ASSUMPTIONS!C23+ASSUMPTIONS!C24)*ASSUMPTIONS!C34*ASSUMPTIONS!B14*(ASSUMPTIONS!B10+ASSUMPTIONS!B9*ASSUMPTIONS!B7*1.1+ASSUMPTIONS!B11)) -> 39971606 | Q7: =((ASSUMPTIONS!C19+ASSUMPTIONS!C20+ASSUMPTIONS!C21+ASSUMPTIONS!C22+ASSUMPTIONS!C23+ASSUMPTIONS!C24+ASSUMPTIONS!C25)*ASSUMPTIONS!C35*ASSUMPTIONS!B14*ASSUMPTIONS!B7*ASSUMPTIONS!B8)-((ASSUMPTIONS!C19+ASSUMPTIONS!C20+ASSUMPTIONS!C21+ASSUMPTIONS!C22+ASSUMPTIONS!C23+ASSUMPTIONS!C24+ASSUMPTIONS!C25)*ASSUMPTIONS!C35*ASSUMPTIONS!B14*(ASSUMPTIONS!B10+ASSUMPTIONS!B9*ASSUMPTIONS!B7*1.1+ASSUMPTIONS!B11)) -> 44106600 | S7: =((ASSUMPTIONS!D19)*ASSUMPTIONS!D29*ASSUMPTIONS!B14*ASSUMPTIONS!B6*ASSUMPTIONS!B8)-((ASSUMPTIONS!D19)*ASSUMPTIONS!D29*ASSUMPTIONS!B14*(ASSUMPTIONS!B10+ASSUMPTIONS!B9*ASSUMPTIONS!B6*1.1+ASSUMPTIONS!B11)) -> 8123987.5 | T7: =((ASSUMPTIONS!D19+ASSUMPTIONS!D20)*ASSUMPTIONS!D30*ASSUMPTIONS!B14*ASSUMPTIONS!B6*ASSUMPTIONS!B8)-((ASSUMPTIONS!D19+ASSUMPTIONS!D20)*ASSUMPTIONS!D30*ASSUMPTIONS!B14*(ASSUMPTIONS!B10+ASSUMPTIONS!B9*ASSUMPTIONS!B6*1.1+ASSUMPTIONS!B11)) -> 29246355 | U7: =((ASSUMPTIONS!D19+ASSUMPTIONS!D20+ASSUMPTIONS!D21)*ASSUMPTIONS!D31*ASSUMPTIONS!B14*ASSUMPTIONS!B7*ASSUMPTIONS!B8)-((ASSUMPTIONS!D19+ASSUMPTIONS!D20+ASSUMPTIONS!D21)*ASSUMPTIONS!D31*ASSUMPTIONS!B14*(ASSUMPTIONS!B10+ASSUMPTIONS!B9*ASSUMPTIONS!B7*1.1+ASSUMPTIONS!B11)) -> 69467895 | V7: =((ASSUMPTIONS!D19+ASSUMPTIONS!D20+ASSUMPTIONS!D21+ASSUMPTIONS!D22)*ASSUMPTIONS!D32*ASSUMPTIONS!B14*ASSUMPTIONS!B7*ASSUMPTIONS!B8)-((ASSUMPTIONS!D19+ASSUMPTIONS!D20+ASSUMPTIONS!D21+ASSUMPTIONS!D22)*ASSUMPTIONS!D32*ASSUMPTIONS!B14*(ASSUMPTIONS!B10+ASSUMPTIONS!B9*ASSUMPTIONS!B7*1.1+ASSUMPTIONS!B11)) -> 97034520 | W7: =((ASSUMPTIONS!D19+ASSUMPTIONS!D20+ASSUMPTIONS!D21+ASSUMPTIONS!D22+ASSUMPTIONS!D23)*ASSUMPTIONS!D33*ASSUMPTIONS!B14*ASSUMPTIONS!B7*ASSUMPTIONS!B8)-((ASSUMPTIONS!D19+ASSUMPTIONS!D20+ASSUMPTIONS!D21+ASSUMPTIONS!D22+ASSUMPTIONS!D23)*ASSUMPTIONS!D33*ASSUMPTIONS!B14*(ASSUMPTIONS!B10+ASSUMPTIONS!B9*ASSUMPTIONS!B7*1.1+ASSUMPTIONS!B11)) -> 114677160 | X7: =((ASSUMPTIONS!D19+ASSUMPTIONS!D20+ASSUMPTIONS!D21+ASSUMPTIONS!D22+ASSUMPTIONS!D23+ASSUMPTIONS!D24)*ASSUMPTIONS!D34*ASSUMPTIONS!B14*ASSUMPTIONS!B7*ASSUMPTIONS!B8)-((ASSUMPTIONS!D19+ASSUMPTIONS!D20+ASSUMPTIONS!D21+ASSUMPTIONS!D22+ASSUMPTIONS!D23+ASSUMPTIONS!D24)*ASSUMPTIONS!D34*ASSUMPTIONS!B14*(ASSUMPTIONS!B10+ASSUMPTIONS!B9*ASSUMPTIONS!B7*1.1+ASSUMPTIONS!B11)) -> 127909140 | Y7: =((ASSUMPTIONS!D19+ASSUMPTIONS!D20+ASSUMPTIONS!D21+ASSUMPTIONS!D22+ASSUMPTIONS!D23+ASSUMPTIONS!D24+ASSUMPTIONS!D25)*ASSUMPTIONS!D35*ASSUMPTIONS!B14*ASSUMPTIONS!B7*ASSUMPTIONS!B8)-((ASSUMPTIONS!D19+ASSUMPTIONS!D20+ASSUMPTIONS!D21+ASSUMPTIONS!D22+ASSUMPTIONS!D23+ASSUMPTIONS!D24+ASSUMPTIONS!D25)*ASSUMPTIONS!D35*ASSUMPTIONS!B14*(ASSUMPTIONS!B10+ASSUMPTIONS!B9*ASSUMPTIONS!B7*1.1+ASSUMPTIONS!B11)) -> 141141120
A8: Free-Lot Convenience Fees | C8: =(ASSUMPTIONS!B19)*ASSUMPTIONS!B29*ASSUMPTIONS!B14*ASSUMPTIONS!B12*ASSUMPTIONS!B13 -> 12964.8 | D8: =(ASSUMPTIONS!B19+ASSUMPTIONS!B20)*ASSUMPTIONS!B30*ASSUMPTIONS!B14*ASSUMPTIONS!B12*ASSUMPTIONS!B13 -> 48618 | E8: =(ASSUMPTIONS!B19+ASSUMPTIONS!B20+ASSUMPTIONS!B21)*ASSUMPTIONS!B31*ASSUMPTIONS!B14*ASSUMPTIONS!B12*ASSUMPTIONS!B13 -> 87512.4 | F8: =(ASSUMPTIONS!B19+ASSUMPTIONS!B20+ASSUMPTIONS!B21+ASSUMPTIONS!B22)*ASSUMPTIONS!B32*ASSUMPTIONS!B14*ASSUMPTIONS!B12*ASSUMPTIONS!B13 -> 133699.5 | G8: =(ASSUMPTIONS!B19+ASSUMPTIONS!B20+ASSUMPTIONS!B21+ASSUMPTIONS!B22+ASSUMPTIONS!B23)*ASSUMPTIONS!B33*ASSUMPTIONS!B14*ASSUMPTIONS!B12*ASSUMPTIONS!B13 -> 158008.5 | H8: =(ASSUMPTIONS!B19+ASSUMPTIONS!B20+ASSUMPTIONS!B21+ASSUMPTIONS!B22+ASSUMPTIONS!B23+ASSUMPTIONS!B24)*ASSUMPTIONS!B34*ASSUMPTIONS!B14*ASSUMPTIONS!B12*ASSUMPTIONS!B13 -> 170163 | I8: =(ASSUMPTIONS!B19+ASSUMPTIONS!B20+ASSUMPTIONS!B21+ASSUMPTIONS!B22+ASSUMPTIONS!B23+ASSUMPTIONS!B24+ASSUMPTIONS!B25)*ASSUMPTIONS!B35*ASSUMPTIONS!B14*ASSUMPTIONS!B12*ASSUMPTIONS!B13 -> 182317.5 | K8: =(ASSUMPTIONS!C19)*ASSUMPTIONS!C29*ASSUMPTIONS!B14*ASSUMPTIONS!B12*ASSUMPTIONS!B13 -> 48618 | L8: =(ASSUMPTIONS!C19+ASSUMPTIONS!C20)*ASSUMPTIONS!C30*ASSUMPTIONS!B14*ASSUMPTIONS!B12*ASSUMPTIONS!B13 -> 175024.8 | M8: =(ASSUMPTIONS!C19+ASSUMPTIONS!C20+ASSUMPTIONS!C21)*ASSUMPTIONS!C31*ASSUMPTIONS!B14*ASSUMPTIONS!B12*ASSUMPTIONS!B13 -> 320878.8 | N8: =(ASSUMPTIONS!C19+ASSUMPTIONS!C20+ASSUMPTIONS!C21+ASSUMPTIONS!C22)*ASSUMPTIONS!C32*ASSUMPTIONS!B14*ASSUMPTIONS!B12*ASSUMPTIONS!B13 -> 445665 | O8: =(ASSUMPTIONS!C19+ASSUMPTIONS!C20+ASSUMPTIONS!C21+ASSUMPTIONS!C22+ASSUMPTIONS!C23)*ASSUMPTIONS!C33*ASSUMPTIONS!B14*ASSUMPTIONS!B12*ASSUMPTIONS!B13 -> 526695 | P8: =(ASSUMPTIONS!C19+ASSUMPTIONS!C20+ASSUMPTIONS!C21+ASSUMPTIONS!C22+ASSUMPTIONS!C23+ASSUMPTIONS!C24)*ASSUMPTIONS!C34*ASSUMPTIONS!B14*ASSUMPTIONS!B12*ASSUMPTIONS!B13 -> 587467.5 | Q8: =(ASSUMPTIONS!C19+ASSUMPTIONS!C20+ASSUMPTIONS!C21+ASSUMPTIONS!C22+ASSUMPTIONS!C23+ASSUMPTIONS!C24+ASSUMPTIONS!C25)*ASSUMPTIONS!C35*ASSUMPTIONS!B14*ASSUMPTIONS!B12*ASSUMPTIONS!B13 -> 648240 | S8: =(ASSUMPTIONS!D19)*ASSUMPTIONS!D29*ASSUMPTIONS!B14*ASSUMPTIONS!B12*ASSUMPTIONS!B13 -> 162060 | T8: =(ASSUMPTIONS!D19+ASSUMPTIONS!D20)*ASSUMPTIONS!D30*ASSUMPTIONS!B14*ASSUMPTIONS!B12*ASSUMPTIONS!B13 -> 583416 | U8: =(ASSUMPTIONS!D19+ASSUMPTIONS!D20+ASSUMPTIONS!D21)*ASSUMPTIONS!D31*ASSUMPTIONS!B14*ASSUMPTIONS!B12*ASSUMPTIONS!B13 -> 1020978 | V8: =(ASSUMPTIONS!D19+ASSUMPTIONS!D20+ASSUMPTIONS!D21+ASSUMPTIONS!D22)*ASSUMPTIONS!D32*ASSUMPTIONS!B14*ASSUMPTIONS!B12*ASSUMPTIONS!B13 -> 1426128 | W8: =(ASSUMPTIONS!D19+ASSUMPTIONS!D20+ASSUMPTIONS!D21+ASSUMPTIONS!D22+ASSUMPTIONS!D23)*ASSUMPTIONS!D33*ASSUMPTIONS!B14*ASSUMPTIONS!B12*ASSUMPTIONS!B13 -> 1685424 | X8: =(ASSUMPTIONS!D19+ASSUMPTIONS!D20+ASSUMPTIONS!D21+ASSUMPTIONS!D22+ASSUMPTIONS!D23+ASSUMPTIONS!D24)*ASSUMPTIONS!D34*ASSUMPTIONS!B14*ASSUMPTIONS!B12*ASSUMPTIONS!B13 -> 1879896 | Y8: =(ASSUMPTIONS!D19+ASSUMPTIONS!D20+ASSUMPTIONS!D21+ASSUMPTIONS!D22+ASSUMPTIONS!D23+ASSUMPTIONS!D24+ASSUMPTIONS!D25)*ASSUMPTIONS!D35*ASSUMPTIONS!B14*ASSUMPTIONS!B12*ASSUMPTIONS!B13 -> 2074368
A9: OEM SaaS (Phase 2, enrolled vehicles × rate) | C9: 0 | D9: 0 | E9: =ASSUMPTIONS!B60*1000*ASSUMPTIONS!B59 -> 125000 | F9: =ASSUMPTIONS!B60*1000*(1+ASSUMPTIONS!B61)^1*ASSUMPTIONS!B59 -> 150000 | G9: =ASSUMPTIONS!B60*1000*(1+ASSUMPTIONS!B61)^2*ASSUMPTIONS!B59 -> 180000 | H9: =ASSUMPTIONS!B60*1000*(1+ASSUMPTIONS!B61)^3*ASSUMPTIONS!B59 -> 216000 | I9: =ASSUMPTIONS!B60*1000*(1+ASSUMPTIONS!B61)^4*ASSUMPTIONS!B59 -> 259200 | K9: 0 | L9: 0 | M9: =ASSUMPTIONS!C60*1000*ASSUMPTIONS!C59 -> 400000 | N9: =ASSUMPTIONS!C60*1000*(1+ASSUMPTIONS!C61)^1*ASSUMPTIONS!C59 -> 560000 | O9: =ASSUMPTIONS!C60*1000*(1+ASSUMPTIONS!C61)^2*ASSUMPTIONS!C59 -> 784000 | P9: =ASSUMPTIONS!C60*1000*(1+ASSUMPTIONS!C61)^3*ASSUMPTIONS!C59 -> 1097600 | Q9: =ASSUMPTIONS!C60*1000*(1+ASSUMPTIONS!C61)^4*ASSUMPTIONS!C59 -> 1536640 | S9: 0 | T9: 0 | U9: =ASSUMPTIONS!D60*1000*ASSUMPTIONS!D59 -> 1500000 | V9: =ASSUMPTIONS!D60*1000*(1+ASSUMPTIONS!D61)^1*ASSUMPTIONS!D59 -> 2400000 | W9: =ASSUMPTIONS!D60*1000*(1+ASSUMPTIONS!D61)^2*ASSUMPTIONS!D59 -> 3840000 | X9: =ASSUMPTIONS!D60*1000*(1+ASSUMPTIONS!D61)^3*ASSUMPTIONS!D59 -> 6144000 | Y9: =ASSUMPTIONS!D60*1000*(1+ASSUMPTIONS!D61)^4*ASSUMPTIONS!D59 -> 9830400
A10: TOTAL REVENUE | C10: =C7+C8+C9 -> 662883.8 | D10: =D7+D8+D9 -> 2485814.2 | E10: =E7+E8+E9 -> 6166903.4 | F10: =F7+F8+F9 -> 9380685.8 | G10: =G7+G8+G9 -> 11088992 | H10: =H7+H8+H9 -> 11964146 | I10: =I7+I8+I9 -> 12846499 | K10: =K7+K8+K9 -> 2485814.2 | L10: =L7+L8+L9 -> 8948931.3 | M10: =M7+M8+M9 -> 22553646 | N10: =N7+N8+N9 -> 31328952 | O10: =O7+O8+O9 -> 37147308 | P10: =P7+P8+P9 -> 41656674 | Q10: =Q7+Q8+Q9 -> 46291480 | S10: =S7+S8+S9 -> 8286047.5 | T10: =T7+T8+T9 -> 29829771 | U10: =U7+U8+U9 -> 71988873 | V10: =V7+V8+V9 -> 100860648 | W10: =W7+W8+W9 -> 120202584 | X10: =X7+X8+X9 -> 135933036 | Y10: =Y7+Y8+Y9 -> 153045888
A12: COST OF REVENUE (COGS)
A13: RSU Hardware Subsidy (new gates × unit cost) | C13: =(ASSUMPTIONS!B19)*IF((ASSUMPTIONS!B19)<ASSUMPTIONS!B41,ASSUMPTIONS!B39,ASSUMPTIONS!B40) -> 20050 | D13: =(ASSUMPTIONS!B20)*IF((ASSUMPTIONS!B19+ASSUMPTIONS!B20)<ASSUMPTIONS!B41,ASSUMPTIONS!B39,ASSUMPTIONS!B40) -> 40100 | E13: =(ASSUMPTIONS!B21)*IF((ASSUMPTIONS!B19+ASSUMPTIONS!B20+ASSUMPTIONS!B21)<ASSUMPTIONS!B41,ASSUMPTIONS!B39,ASSUMPTIONS!B40) -> 17625 | F13: =(ASSUMPTIONS!B22)*IF((ASSUMPTIONS!B19+ASSUMPTIONS!B20+ASSUMPTIONS!B21+ASSUMPTIONS!B22)<ASSUMPTIONS!B41,ASSUMPTIONS!B39,ASSUMPTIONS!B40) -> 11750 | G13: =(ASSUMPTIONS!B23)*IF((ASSUMPTIONS!B19+ASSUMPTIONS!B20+ASSUMPTIONS!B21+ASSUMPTIONS!B22+ASSUMPTIONS!B23)<ASSUMPTIONS!B41,ASSUMPTIONS!B39,ASSUMPTIONS!B40) -> 11750 | H13: =(ASSUMPTIONS!B24)*IF((ASSUMPTIONS!B19+ASSUMPTIONS!B20+ASSUMPTIONS!B21+ASSUMPTIONS!B22+ASSUMPTIONS!B23+ASSUMPTIONS!B24)<ASSUMPTIONS!B41,ASSUMPTIONS!B39,ASSUMPTIONS!B40) -> 5875 | I13: =(ASSUMPTIONS!B25)*IF((ASSUMPTIONS!B19+ASSUMPTIONS!B20+ASSUMPTIONS!B21+ASSUMPTIONS!B22+ASSUMPTIONS!B23+ASSUMPTIONS!B24+ASSUMPTIONS!B25)<ASSUMPTIONS!B41,ASSUMPTIONS!B39,ASSUMPTIONS!B40) -> 5875 | K13: =(ASSUMPTIONS!C19)*IF((ASSUMPTIONS!C19)<ASSUMPTIONS!B41,ASSUMPTIONS!B39,ASSUMPTIONS!B40) -> 40100 | L13: =(ASSUMPTIONS!C20)*IF((ASSUMPTIONS!C19+ASSUMPTIONS!C20)<ASSUMPTIONS!B41,ASSUMPTIONS!B39,ASSUMPTIONS!B40) -> 47000 | M13: =(ASSUMPTIONS!C21)*IF((ASSUMPTIONS!C19+ASSUMPTIONS!C20+ASSUMPTIONS!C21)<ASSUMPTIONS!B41,ASSUMPTIONS!B39,ASSUMPTIONS!B40) -> 35250 | N13: =(ASSUMPTIONS!C22)*IF((ASSUMPTIONS!C19+ASSUMPTIONS!C20+ASSUMPTIONS!C21+ASSUMPTIONS!C22)<ASSUMPTIONS!B41,ASSUMPTIONS!B39,ASSUMPTIONS!B40) -> 23500 | O13: =(ASSUMPTIONS!C23)*IF((ASSUMPTIONS!C19+ASSUMPTIONS!C20+ASSUMPTIONS!C21+ASSUMPTIONS!C22+ASSUMPTIONS!C23)<ASSUMPTIONS!B41,ASSUMPTIONS!B39,ASSUMPTIONS!B40) -> 23500 | P13: =(ASSUMPTIONS!C24)*IF((ASSUMPTIONS!C19+ASSUMPTIONS!C20+ASSUMPTIONS!C21+ASSUMPTIONS!C22+ASSUMPTIONS!C23+ASSUMPTIONS!C24)<ASSUMPTIONS!B41,ASSUMPTIONS!B39,ASSUMPTIONS!B40) -> 17625 | Q13: =(ASSUMPTIONS!C25)*IF((ASSUMPTIONS!C19+ASSUMPTIONS!C20+ASSUMPTIONS!C21+ASSUMPTIONS!C22+ASSUMPTIONS!C23+ASSUMPTIONS!C24+ASSUMPTIONS!C25)<ASSUMPTIONS!B41,ASSUMPTIONS!B39,ASSUMPTIONS!B40) -> 17625 | S13: =(ASSUMPTIONS!D19)*IF((ASSUMPTIONS!D19)<ASSUMPTIONS!B41,ASSUMPTIONS!B39,ASSUMPTIONS!B40) -> 47000 | T13: =(ASSUMPTIONS!D20)*IF((ASSUMPTIONS!D19+ASSUMPTIONS!D20)<ASSUMPTIONS!B41,ASSUMPTIONS!B39,ASSUMPTIONS!B40) -> 94000 | U13: =(ASSUMPTIONS!D21)*IF((ASSUMPTIONS!D19+ASSUMPTIONS!D20+ASSUMPTIONS!D21)<ASSUMPTIONS!B41,ASSUMPTIONS!B39,ASSUMPTIONS!B40) -> 70500 | V13: =(ASSUMPTIONS!D22)*IF((ASSUMPTIONS!D19+ASSUMPTIONS!D20+ASSUMPTIONS!D21+ASSUMPTIONS!D22)<ASSUMPTIONS!B41,ASSUMPTIONS!B39,ASSUMPTIONS!B40) -> 47000 | W13: =(ASSUMPTIONS!D23)*IF((ASSUMPTIONS!D19+ASSUMPTIONS!D20+ASSUMPTIONS!D21+ASSUMPTIONS!D22+ASSUMPTIONS!D23)<ASSUMPTIONS!B41,ASSUMPTIONS!B39,ASSUMPTIONS!B40) -> 47000 | X13: =(ASSUMPTIONS!D24)*IF((ASSUMPTIONS!D19+ASSUMPTIONS!D20+ASSUMPTIONS!D21+ASSUMPTIONS!D22+ASSUMPTIONS!D23+ASSUMPTIONS!D24)<ASSUMPTIONS!B41,ASSUMPTIONS!B39,ASSUMPTIONS!B40) -> 35250 | Y13: =(ASSUMPTIONS!D25)*IF((ASSUMPTIONS!D19+ASSUMPTIONS!D20+ASSUMPTIONS!D21+ASSUMPTIONS!D22+ASSUMPTIONS!D23+ASSUMPTIONS!D24+ASSUMPTIONS!D25)<ASSUMPTIONS!B41,ASSUMPTIONS!B39,ASSUMPTIONS!B40) -> 35250
A14: Stripe Processing Fees | C14: =(ASSUMPTIONS!B19)*ASSUMPTIONS!B29*ASSUMPTIONS!B14*(ASSUMPTIONS!B10+ASSUMPTIONS!B9*ASSUMPTIONS!B6*1.1+ASSUMPTIONS!B11) -> 116581 | D14: =(ASSUMPTIONS!B19+ASSUMPTIONS!B20)*ASSUMPTIONS!B30*ASSUMPTIONS!B14*(ASSUMPTIONS!B10+ASSUMPTIONS!B9*ASSUMPTIONS!B6*1.1+ASSUMPTIONS!B11) -> 437178.75 | E14: =(ASSUMPTIONS!B19+ASSUMPTIONS!B20+ASSUMPTIONS!B21)*ASSUMPTIONS!B31*ASSUMPTIONS!B14*(ASSUMPTIONS!B10+ASSUMPTIONS!B9*ASSUMPTIONS!B7*1.1+ASSUMPTIONS!B11) -> 944109 | F14: =(ASSUMPTIONS!B19+ASSUMPTIONS!B20+ASSUMPTIONS!B21+ASSUMPTIONS!B22)*ASSUMPTIONS!B32*ASSUMPTIONS!B14*(ASSUMPTIONS!B10+ASSUMPTIONS!B9*ASSUMPTIONS!B7*1.1+ASSUMPTIONS!B11) -> 1442388.8 | G14: =(ASSUMPTIONS!B19+ASSUMPTIONS!B20+ASSUMPTIONS!B21+ASSUMPTIONS!B22+ASSUMPTIONS!B23)*ASSUMPTIONS!B33*ASSUMPTIONS!B14*(ASSUMPTIONS!B10+ASSUMPTIONS!B9*ASSUMPTIONS!B7*1.1+ASSUMPTIONS!B11) -> 1704641.2 | H14: =(ASSUMPTIONS!B19+ASSUMPTIONS!B20+ASSUMPTIONS!B21+ASSUMPTIONS!B22+ASSUMPTIONS!B23+ASSUMPTIONS!B24)*ASSUMPTIONS!B34*ASSUMPTIONS!B14*(ASSUMPTIONS!B10+ASSUMPTIONS!B9*ASSUMPTIONS!B7*1.1+ASSUMPTIONS!B11) -> 1835767.5 | I14: =(ASSUMPTIONS!B19+ASSUMPTIONS!B20+ASSUMPTIONS!B21+ASSUMPTIONS!B22+ASSUMPTIONS!B23+ASSUMPTIONS!B24+ASSUMPTIONS!B25)*ASSUMPTIONS!B35*ASSUMPTIONS!B14*(ASSUMPTIONS!B10+ASSUMPTIONS!B9*ASSUMPTIONS!B7*1.1+ASSUMPTIONS!B11) -> 1966893.8 | K14: =(ASSUMPTIONS!C19)*ASSUMPTIONS!C29*ASSUMPTIONS!B14*(ASSUMPTIONS!B10+ASSUMPTIONS!B9*ASSUMPTIONS!B6*1.1+ASSUMPTIONS!B11) -> 437178.75 | L14: =(ASSUMPTIONS!C19+ASSUMPTIONS!C20)*ASSUMPTIONS!C30*ASSUMPTIONS!B14*(ASSUMPTIONS!B10+ASSUMPTIONS!B9*ASSUMPTIONS!B6*1.1+ASSUMPTIONS!B11) -> 1573843.5 | M14: =(ASSUMPTIONS!C19+ASSUMPTIONS!C20+ASSUMPTIONS!C21)*ASSUMPTIONS!C31*ASSUMPTIONS!B14*(ASSUMPTIONS!B10+ASSUMPTIONS!B9*ASSUMPTIONS!B7*1.1+ASSUMPTIONS!B11) -> 3461733 | N14: =(ASSUMPTIONS!C19+ASSUMPTIONS!C20+ASSUMPTIONS!C21+ASSUMPTIONS!C22)*ASSUMPTIONS!C32*ASSUMPTIONS!B14*(ASSUMPTIONS!B10+ASSUMPTIONS!B9*ASSUMPTIONS!B7*1.1+ASSUMPTIONS!B11) -> 4807962.5 | O14: =(ASSUMPTIONS!C19+ASSUMPTIONS!C20+ASSUMPTIONS!C21+ASSUMPTIONS!C22+ASSUMPTIONS!C23)*ASSUMPTIONS!C33*ASSUMPTIONS!B14*(ASSUMPTIONS!B10+ASSUMPTIONS!B9*ASSUMPTIONS!B7*1.1+ASSUMPTIONS!B11) -> 5682137.5 | P14: =(ASSUMPTIONS!C19+ASSUMPTIONS!C20+ASSUMPTIONS!C21+ASSUMPTIONS!C22+ASSUMPTIONS!C23+ASSUMPTIONS!C24)*ASSUMPTIONS!C34*ASSUMPTIONS!B14*(ASSUMPTIONS!B10+ASSUMPTIONS!B9*ASSUMPTIONS!B7*1.1+ASSUMPTIONS!B11) -> 6337768.8 | Q14: =(ASSUMPTIONS!C19+ASSUMPTIONS!C20+ASSUMPTIONS!C21+ASSUMPTIONS!C22+ASSUMPTIONS!C23+ASSUMPTIONS!C24+ASSUMPTIONS!C25)*ASSUMPTIONS!C35*ASSUMPTIONS!B14*(ASSUMPTIONS!B10+ASSUMPTIONS!B9*ASSUMPTIONS!B7*1.1+ASSUMPTIONS!B11) -> 6993400 | S14: =(ASSUMPTIONS!D19)*ASSUMPTIONS!D29*ASSUMPTIONS!B14*(ASSUMPTIONS!B10+ASSUMPTIONS!B9*ASSUMPTIONS!B6*1.1+ASSUMPTIONS!B11) -> 1457262.5 | T14: =(ASSUMPTIONS!D19+ASSUMPTIONS!D20)*ASSUMPTIONS!D30*ASSUMPTIONS!B14*(ASSUMPTIONS!B10+ASSUMPTIONS!B9*ASSUMPTIONS!B6*1.1+ASSUMPTIONS!B11) -> 5246145 | U14: =(ASSUMPTIONS!D19+ASSUMPTIONS!D20+ASSUMPTIONS!D21)*ASSUMPTIONS!D31*ASSUMPTIONS!B14*(ASSUMPTIONS!B10+ASSUMPTIONS!B9*ASSUMPTIONS!B7*1.1+ASSUMPTIONS!B11) -> 11014605 | V14: =(ASSUMPTIONS!D19+ASSUMPTIONS!D20+ASSUMPTIONS!D21+ASSUMPTIONS!D22)*ASSUMPTIONS!D32*ASSUMPTIONS!B14*(ASSUMPTIONS!B10+ASSUMPTIONS!B9*ASSUMPTIONS!B7*1.1+ASSUMPTIONS!B11) -> 15385480 | W14: =(ASSUMPTIONS!D19+ASSUMPTIONS!D20+ASSUMPTIONS!D21+ASSUMPTIONS!D22+ASSUMPTIONS!D23)*ASSUMPTIONS!D33*ASSUMPTIONS!B14*(ASSUMPTIONS!B10+ASSUMPTIONS!B9*ASSUMPTIONS!B7*1.1+ASSUMPTIONS!B11) -> 18182840 | X14: =(ASSUMPTIONS!D19+ASSUMPTIONS!D20+ASSUMPTIONS!D21+ASSUMPTIONS!D22+ASSUMPTIONS!D23+ASSUMPTIONS!D24)*ASSUMPTIONS!D34*ASSUMPTIONS!B14*(ASSUMPTIONS!B10+ASSUMPTIONS!B9*ASSUMPTIONS!B7*1.1+ASSUMPTIONS!B11) -> 20280860 | Y14: =(ASSUMPTIONS!D19+ASSUMPTIONS!D20+ASSUMPTIONS!D21+ASSUMPTIONS!D22+ASSUMPTIONS!D23+ASSUMPTIONS!D24+ASSUMPTIONS!D25)*ASSUMPTIONS!D35*ASSUMPTIONS!B14*(ASSUMPTIONS!B10+ASSUMPTIONS!B9*ASSUMPTIONS!B7*1.1+ASSUMPTIONS!B11) -> 22378880
A15: Cloud Infrastructure (per gate × $85/yr) | C15: =(ASSUMPTIONS!B19)*ASSUMPTIONS!B48 -> 4250 | D15: =(ASSUMPTIONS!B19+ASSUMPTIONS!B20)*ASSUMPTIONS!B48 -> 12750 | E15: =(ASSUMPTIONS!B19+ASSUMPTIONS!B20+ASSUMPTIONS!B21)*ASSUMPTIONS!B48 -> 19125 | F15: =(ASSUMPTIONS!B19+ASSUMPTIONS!B20+ASSUMPTIONS!B21+ASSUMPTIONS!B22)*ASSUMPTIONS!B48 -> 23375 | G15: =(ASSUMPTIONS!B19+ASSUMPTIONS!B20+ASSUMPTIONS!B21+ASSUMPTIONS!B22+ASSUMPTIONS!B23)*ASSUMPTIONS!B48 -> 27625 | H15: =(ASSUMPTIONS!B19+ASSUMPTIONS!B20+ASSUMPTIONS!B21+ASSUMPTIONS!B22+ASSUMPTIONS!B23+ASSUMPTIONS!B24)*ASSUMPTIONS!B48 -> 29750 | I15: =(ASSUMPTIONS!B19+ASSUMPTIONS!B20+ASSUMPTIONS!B21+ASSUMPTIONS!B22+ASSUMPTIONS!B23+ASSUMPTIONS!B24+ASSUMPTIONS!B25)*ASSUMPTIONS!B48 -> 31875 | K15: =(ASSUMPTIONS!C19)*ASSUMPTIONS!B48 -> 8500 | L15: =(ASSUMPTIONS!C19+ASSUMPTIONS!C20)*ASSUMPTIONS!B48 -> 25500 | M15: =(ASSUMPTIONS!C19+ASSUMPTIONS!C20+ASSUMPTIONS!C21)*ASSUMPTIONS!B48 -> 38250 | N15: =(ASSUMPTIONS!C19+ASSUMPTIONS!C20+ASSUMPTIONS!C21+ASSUMPTIONS!C22)*ASSUMPTIONS!B48 -> 46750 | O15: =(ASSUMPTIONS!C19+ASSUMPTIONS!C20+ASSUMPTIONS!C21+ASSUMPTIONS!C22+ASSUMPTIONS!C23)*ASSUMPTIONS!B48 -> 55250 | P15: =(ASSUMPTIONS!C19+ASSUMPTIONS!C20+ASSUMPTIONS!C21+ASSUMPTIONS!C22+ASSUMPTIONS!C23+ASSUMPTIONS!C24)*ASSUMPTIONS!B48 -> 61625 | Q15: =(ASSUMPTIONS!C19+ASSUMPTIONS!C20+ASSUMPTIONS!C21+ASSUMPTIONS!C22+ASSUMPTIONS!C23+ASSUMPTIONS!C24+ASSUMPTIONS!C25)*ASSUMPTIONS!B48 -> 68000 | S15: =(ASSUMPTIONS!D19)*ASSUMPTIONS!B48 -> 17000 | T15: =(ASSUMPTIONS!D19+ASSUMPTIONS!D20)*ASSUMPTIONS!B48 -> 51000 | U15: =(ASSUMPTIONS!D19+ASSUMPTIONS!D20+ASSUMPTIONS!D21)*ASSUMPTIONS!B48 -> 76500 | V15: =(ASSUMPTIONS!D19+ASSUMPTIONS!D20+ASSUMPTIONS!D21+ASSUMPTIONS!D22)*ASSUMPTIONS!B48 -> 93500 | W15: =(ASSUMPTIONS!D19+ASSUMPTIONS!D20+ASSUMPTIONS!D21+ASSUMPTIONS!D22+ASSUMPTIONS!D23)*ASSUMPTIONS!B48 -> 110500 | X15: =(ASSUMPTIONS!D19+ASSUMPTIONS!D20+ASSUMPTIONS!D21+ASSUMPTIONS!D22+ASSUMPTIONS!D23+ASSUMPTIONS!D24)*ASSUMPTIONS!B48 -> 123250 | Y15: =(ASSUMPTIONS!D19+ASSUMPTIONS!D20+ASSUMPTIONS!D21+ASSUMPTIONS!D22+ASSUMPTIONS!D23+ASSUMPTIONS!D24+ASSUMPTIONS!D25)*ASSUMPTIONS!B48 -> 136000
A16: Parkopedia API (annual) | C16: =ASSUMPTIONS!B49 -> 14400 | D16: =ASSUMPTIONS!B49 -> 14400 | E16: =ASSUMPTIONS!B49 -> 14400 | F16: =ASSUMPTIONS!B49 -> 14400 | G16: =ASSUMPTIONS!B49 -> 14400 | H16: =ASSUMPTIONS!B49 -> 14400 | I16: =ASSUMPTIONS!B49 -> 14400 | K16: =ASSUMPTIONS!B49 -> 14400 | L16: =ASSUMPTIONS!B49 -> 14400 | M16: =ASSUMPTIONS!B49 -> 14400 | N16: =ASSUMPTIONS!B49 -> 14400 | O16: =ASSUMPTIONS!B49 -> 14400 | P16: =ASSUMPTIONS!B49 -> 14400 | Q16: =ASSUMPTIONS!B49 -> 14400 | S16: =ASSUMPTIONS!B49 -> 14400 | T16: =ASSUMPTIONS!B49 -> 14400 | U16: =ASSUMPTIONS!B49 -> 14400 | V16: =ASSUMPTIONS!B49 -> 14400 | W16: =ASSUMPTIONS!B49 -> 14400 | X16: =ASSUMPTIONS!B49 -> 14400 | Y16: =ASSUMPTIONS!B49 -> 14400
A17: TOTAL COGS | C17: =C13+C14+C15+C16 -> 155281 | D17: =D13+D14+D15+D16 -> 504428.75 | E17: =E13+E14+E15+E16 -> 995259 | F17: =F13+F14+F15+F16 -> 1491913.8 | G17: =G13+G14+G15+G16 -> 1758416.2 | H17: =H13+H14+H15+H16 -> 1885792.5 | I17: =I13+I14+I15+I16 -> 2019043.8 | K17: =K13+K14+K15+K16 -> 500178.75 | L17: =L13+L14+L15+L16 -> 1660743.5 | M17: =M13+M14+M15+M16 -> 3549633 | N17: =N13+N14+N15+N16 -> 4892612.5 | O17: =O13+O14+O15+O16 -> 5775287.5 | P17: =P13+P14+P15+P16 -> 6431418.8 | Q17: =Q13+Q14+Q15+Q16 -> 7093425 | S17: =S13+S14+S15+S16 -> 1535662.5 | T17: =T13+T14+T15+T16 -> 5405545 | U17: =U13+U14+U15+U16 -> 11176005 | V17: =V13+V14+V15+V16 -> 15540380 | W17: =W13+W14+W15+W16 -> 18354740 | X17: =X13+X14+X15+X16 -> 20453760 | Y17: =Y13+Y14+Y15+Y16 -> 22564530
A18: GROSS PROFIT | C18: =C10-C17 -> 507602.8 | D18: =D10-D17 -> 1981385.5 | E18: =E10-E17 -> 5171644.4 | F18: =F10-F17 -> 7888772 | G18: =G10-G17 -> 9330576 | H18: =H10-H17 -> 10078353 | I18: =I10-I17 -> 10827455 | K18: =K10-K17 -> 1985635.5 | L18: =L10-L17 -> 7288187.8 | M18: =M10-M17 -> 19004013 | N18: =N10-N17 -> 26436340 | O18: =O10-O17 -> 31372020 | P18: =P10-P17 -> 35225255 | Q18: =Q10-Q17 -> 39198055 | S18: =S10-S17 -> 6750385 | T18: =T10-T17 -> 24424226 | U18: =U10-U17 -> 60812868 | V18: =V10-V17 -> 85320268 | W18: =W10-W17 -> 101847844 | X18: =X10-X17 -> 115479276 | Y18: =Y10-Y17 -> 130481358
A19: Gross Margin % | C19: =IFERROR(C18/C10,"-") -> 0.76574929 | D19: =IFERROR(D18/D10,"-") -> 0.79707705 | E19: =IFERROR(E18/E10,"-") -> 0.83861284 | F19: =IFERROR(F18/F10,"-") -> 0.84095899 | G19: =IFERROR(G18/G10,"-") -> 0.84142687 | H19: =IFERROR(H18/H10,"-") -> 0.84237968 | I19: =IFERROR(I18/I10,"-") -> 0.84283315 | K19: =IFERROR(K18/K10,"-") -> 0.79878676 | L19: =IFERROR(L18/L10,"-") -> 0.81441991 | M19: =IFERROR(M18/M10,"-") -> 0.84261378 | N19: =IFERROR(N18/N10,"-") -> 0.84383096 | O19: =IFERROR(O18/O10,"-") -> 0.84453012 | P19: =IFERROR(P18/P10,"-") -> 0.84560892 | Q19: =IFERROR(Q18/Q10,"-") -> 0.84676608 | S19: =IFERROR(S18/S10,"-") -> 0.81466888 | T19: =IFERROR(T18/T10,"-") -> 0.81878691 | U19: =IFERROR(U18/U10,"-") -> 0.84475372 | V19: =IFERROR(V18/V10,"-") -> 0.84592227 | W19: =IFERROR(W18/W10,"-") -> 0.84730162 | X19: =IFERROR(X18/X10,"-") -> 0.84953062 | Y19: =IFERROR(Y18/Y10,"-") -> 0.85256363
A21: OPERATING EXPENSES
A22: Research & Development | C22: =ASSUMPTIONS!B50 -> 15000 | D22: =ASSUMPTIONS!B51 -> 285000 | E22: =ASSUMPTIONS!B52 -> 520000 | F22: =ASSUMPTIONS!B53 -> 600000 | G22: =ASSUMPTIONS!B53 -> 600000 | H22: =ASSUMPTIONS!B53 -> 600000 | I22: =ASSUMPTIONS!B53 -> 600000 | K22: =ASSUMPTIONS!B50 -> 15000 | L22: =ASSUMPTIONS!B51 -> 285000 | M22: =ASSUMPTIONS!B52 -> 520000 | N22: =ASSUMPTIONS!B53 -> 600000 | O22: =ASSUMPTIONS!B53 -> 600000 | P22: =ASSUMPTIONS!B53 -> 600000 | Q22: =ASSUMPTIONS!B53 -> 600000 | S22: =ASSUMPTIONS!B50 -> 15000 | T22: =ASSUMPTIONS!B51 -> 285000 | U22: =ASSUMPTIONS!B52 -> 520000 | V22: =ASSUMPTIONS!B53 -> 600000 | W22: =ASSUMPTIONS!B53 -> 600000 | X22: =ASSUMPTIONS!B53 -> 600000 | Y22: =ASSUMPTIONS!B53 -> 600000
A23: Sales & Marketing (15% of revenue) | C23: =C10*ASSUMPTIONS!B54 -> 99432.57 | D23: =D10*ASSUMPTIONS!B54 -> 372872.14 | E23: =E10*ASSUMPTIONS!B54 -> 925035.51 | F23: =F10*ASSUMPTIONS!B54 -> 1407102.9 | G23: =G10*ASSUMPTIONS!B54 -> 1663348.8 | H23: =H10*ASSUMPTIONS!B54 -> 1794621.8 | I23: =I10*ASSUMPTIONS!B54 -> 1926974.8 | K23: =K10*ASSUMPTIONS!B54 -> 372872.14 | L23: =L10*ASSUMPTIONS!B54 -> 1342339.7 | M23: =M10*ASSUMPTIONS!B54 -> 3383046.9 | N23: =N10*ASSUMPTIONS!B54 -> 4699342.9 | O23: =O10*ASSUMPTIONS!B54 -> 5572096.1 | P23: =P10*ASSUMPTIONS!B54 -> 6248501.1 | Q23: =Q10*ASSUMPTIONS!B54 -> 6943722 | S23: =S10*ASSUMPTIONS!B54 -> 1242907.1 | T23: =T10*ASSUMPTIONS!B54 -> 4474465.7 | U23: =U10*ASSUMPTIONS!B54 -> 10798331 | V23: =V10*ASSUMPTIONS!B54 -> 15129097 | W23: =W10*ASSUMPTIONS!B54 -> 18030388 | X23: =X10*ASSUMPTIONS!B54 -> 20389955 | Y23: =Y10*ASSUMPTIONS!B54 -> 22956883
A24: General & Administrative | C24: =ASSUMPTIONS!B55 -> 50000 | D24: =ASSUMPTIONS!B55*(1.1)^1 -> 55000 | E24: =ASSUMPTIONS!B55*(1.1)^2 -> 60500 | F24: =ASSUMPTIONS!B55*(1.1)^3 -> 66550 | G24: =ASSUMPTIONS!B55*(1.1)^4 -> 73205 | H24: =ASSUMPTIONS!B55*(1.1)^5 -> 80525.5 | I24: =ASSUMPTIONS!B55*(1.1)^6 -> 88578.05 | K24: =ASSUMPTIONS!B55 -> 50000 | L24: =ASSUMPTIONS!B55*(1.1)^1 -> 55000 | M24: =ASSUMPTIONS!B55*(1.1)^2 -> 60500 | N24: =ASSUMPTIONS!B55*(1.1)^3 -> 66550 | O24: =ASSUMPTIONS!B55*(1.1)^4 -> 73205 | P24: =ASSUMPTIONS!B55*(1.1)^5 -> 80525.5 | Q24: =ASSUMPTIONS!B55*(1.1)^6 -> 88578.05 | S24: =ASSUMPTIONS!B55 -> 50000 | T24: =ASSUMPTIONS!B55*(1.1)^1 -> 55000 | U24: =ASSUMPTIONS!B55*(1.1)^2 -> 60500 | V24: =ASSUMPTIONS!B55*(1.1)^3 -> 66550 | W24: =ASSUMPTIONS!B55*(1.1)^4 -> 73205 | X24: =ASSUMPTIONS!B55*(1.1)^5 -> 80525.5 | Y24: =ASSUMPTIONS!B55*(1.1)^6 -> 88578.05
A25: TOTAL OPEX | C25: =C22+C23+C24 -> 164432.57 | D25: =D22+D23+D24 -> 712872.14 | E25: =E22+E23+E24 -> 1505535.5 | F25: =F22+F23+F24 -> 2073652.9 | G25: =G22+G23+G24 -> 2336553.8 | H25: =H22+H23+H24 -> 2475147.3 | I25: =I22+I23+I24 -> 2615552.9 | K25: =K22+K23+K24 -> 437872.14 | L25: =L22+L23+L24 -> 1682339.7 | M25: =M22+M23+M24 -> 3963546.9 | N25: =N22+N23+N24 -> 5365892.9 | O25: =O22+O23+O24 -> 6245301.1 | P25: =P22+P23+P24 -> 6929026.6 | Q25: =Q22+Q23+Q24 -> 7632300 | S25: =S22+S23+S24 -> 1307907.1 | T25: =T22+T23+T24 -> 4814465.7 | U25: =U22+U23+U24 -> 11378831 | V25: =V22+V23+V24 -> 15795647 | W25: =W22+W23+W24 -> 18703593 | X25: =X22+X23+X24 -> 21070481 | Y25: =Y22+Y23+Y24 -> 23645461
A26: EBITDA (Net Income / Loss) | C26: =C18-C25 -> 343170.23 | D26: =D18-D25 -> 1268513.4 | E26: =E18-E25 -> 3666108.9 | F26: =F18-F25 -> 5815119.1 | G26: =G18-G25 -> 6994022.2 | H26: =H18-H25 -> 7603205.7 | I26: =I18-I25 -> 8211902.1 | K26: =K18-K25 -> 1547763.4 | L26: =L18-L25 -> 5605848.1 | M26: =M18-M25 -> 15040466 | N26: =N18-N25 -> 21070447 | O26: =O18-O25 -> 25126719 | P26: =P18-P25 -> 28296228 | Q26: =Q18-Q25 -> 31565755 | S26: =S18-S25 -> 5442477.9 | T26: =T18-T25 -> 19609760 | U26: =U18-U25 -> 49434037 | V26: =V18-V25 -> 69524621 | W26: =W18-W25 -> 83144251 | X26: =X18-X25 -> 94408795 | Y26: =Y18-Y25 -> 1.068359e+08
A27: EBITDA Margin % | C27: =IFERROR(C26/C10,"-") -> 0.51769289 | D27: =IFERROR(D26/D10,"-") -> 0.51030095 | E27: =IFERROR(E26/E10,"-") -> 0.59448132 | F27: =IFERROR(F26/F10,"-") -> 0.61990342 | G27: =IFERROR(G26/G10,"-") -> 0.63071756 | H27: =IFERROR(H26/H10,"-") -> 0.63549927 | I27: =IFERROR(I26/I10,"-") -> 0.6392327 | K27: =IFERROR(K26/K10,"-") -> 0.62263838 | L27: =IFERROR(L26/L10,"-") -> 0.62642654 | M27: =IFERROR(M26/M10,"-") -> 0.66687515 | N27: =IFERROR(N26/N10,"-") -> 0.67255511 | O27: =IFERROR(O26/O10,"-") -> 0.67640754 | P27: =IFERROR(P26/P10,"-") -> 0.67927239 | Q27: =IFERROR(Q26/Q10,"-") -> 0.68189125 | S27: =IFERROR(S26/S10,"-") -> 0.65682436 | T27: =IFERROR(T26/T10,"-") -> 0.6573889 | U27: =IFERROR(U26/U10,"-") -> 0.68668997 | V27: =IFERROR(V26/V10,"-") -> 0.68931364 | W27: =IFERROR(W26/W10,"-") -> 0.69170103 | X27: =IFERROR(X26/X10,"-") -> 0.69452429 | Y27: =IFERROR(Y26/Y10,"-") -> 0.69806447
A29: CUMULATIVE CASH POSITION (FROM EBITDA PROXY)
A30: Cumulative EBITDA (cash proxy) | C30: =C26 -> 343170.23 | D30: =C30+D26 -> 1611683.6 | E30: =D30+E26 -> 5277792.5 | F30: =E30+F26 -> 11092912 | G30: =F30+G26 -> 18086934 | H30: =G30+H26 -> 25690139 | I30: =H30+I26 -> 33902042 | K30: =K26 -> 1547763.4 | L30: =K30+L26 -> 7153611.5 | M30: =L30+M26 -> 22194077 | N30: =M30+N26 -> 43264525 | O30: =N30+O26 -> 68391243 | P30: =O30+P26 -> 96687472 | Q30: =P30+Q26 -> 1.2825323e+08 | S30: =S26 -> 5442477.9 | T30: =S30+T26 -> 25052238 | U30: =T30+U26 -> 74486275 | V30: =U30+V26 -> 1.440109e+08 | W30: =V30+W26 -> 2.2715515e+08 | X30: =W30+X26 -> 3.2156394e+08 | Y30: =X30+Y26 -> 4.2839984e+08
A32: OPERATING METRICS
A33: Cumulative RSU Gates Deployed | C33: =ASSUMPTIONS!B19 -> 50 | D33: =ASSUMPTIONS!B19+ASSUMPTIONS!B20 -> 150 | E33: =ASSUMPTIONS!B19+ASSUMPTIONS!B20+ASSUMPTIONS!B21 -> 225 | F33: =ASSUMPTIONS!B19+ASSUMPTIONS!B20+ASSUMPTIONS!B21+ASSUMPTIONS!B22 -> 275 | G33: =ASSUMPTIONS!B19+ASSUMPTIONS!B20+ASSUMPTIONS!B21+ASSUMPTIONS!B22+ASSUMPTIONS!B23 -> 325 | H33: =ASSUMPTIONS!B19+ASSUMPTIONS!B20+ASSUMPTIONS!B21+ASSUMPTIONS!B22+ASSUMPTIONS!B23+ASSUMPTIONS!B24 -> 350 | I33: =ASSUMPTIONS!B19+ASSUMPTIONS!B20+ASSUMPTIONS!B21+ASSUMPTIONS!B22+ASSUMPTIONS!B23+ASSUMPTIONS!B24+ASSUMPTIONS!B25 -> 375 | K33: =ASSUMPTIONS!C19 -> 100 | L33: =ASSUMPTIONS!C19+ASSUMPTIONS!C20 -> 300 | M33: =ASSUMPTIONS!C19+ASSUMPTIONS!C20+ASSUMPTIONS!C21 -> 450 | N33: =ASSUMPTIONS!C19+ASSUMPTIONS!C20+ASSUMPTIONS!C21+ASSUMPTIONS!C22 -> 550 | O33: =ASSUMPTIONS!C19+ASSUMPTIONS!C20+ASSUMPTIONS!C21+ASSUMPTIONS!C22+ASSUMPTIONS!C23 -> 650 | P33: =ASSUMPTIONS!C19+ASSUMPTIONS!C20+ASSUMPTIONS!C21+ASSUMPTIONS!C22+ASSUMPTIONS!C23+ASSUMPTIONS!C24 -> 725 | Q33: =ASSUMPTIONS!C19+ASSUMPTIONS!C20+ASSUMPTIONS!C21+ASSUMPTIONS!C22+ASSUMPTIONS!C23+ASSUMPTIONS!C24+ASSUMPTIONS!C25 -> 800 | S33: =ASSUMPTIONS!D19 -> 200 | T33: =ASSUMPTIONS!D19+ASSUMPTIONS!D20 -> 600 | U33: =ASSUMPTIONS!D19+ASSUMPTIONS!D20+ASSUMPTIONS!D21 -> 900 | V33: =ASSUMPTIONS!D19+ASSUMPTIONS!D20+ASSUMPTIONS!D21+ASSUMPTIONS!D22 -> 1100 | W33: =ASSUMPTIONS!D19+ASSUMPTIONS!D20+ASSUMPTIONS!D21+ASSUMPTIONS!D22+ASSUMPTIONS!D23 -> 1300 | X33: =ASSUMPTIONS!D19+ASSUMPTIONS!D20+ASSUMPTIONS!D21+ASSUMPTIONS!D22+ASSUMPTIONS!D23+ASSUMPTIONS!D24 -> 1450 | Y33: =ASSUMPTIONS!D19+ASSUMPTIONS!D20+ASSUMPTIONS!D21+ASSUMPTIONS!D22+ASSUMPTIONS!D23+ASSUMPTIONS!D24+ASSUMPTIONS!D25 -> 1600
A34: Annual Parking Transactions | C34: =(ASSUMPTIONS!B19)*ASSUMPTIONS!B29*ASSUMPTIONS!B14 -> 146000 | D34: =(ASSUMPTIONS!B19+ASSUMPTIONS!B20)*ASSUMPTIONS!B30*ASSUMPTIONS!B14 -> 547500 | E34: =(ASSUMPTIONS!B19+ASSUMPTIONS!B20+ASSUMPTIONS!B21)*ASSUMPTIONS!B31*ASSUMPTIONS!B14 -> 985500 | F34: =(ASSUMPTIONS!B19+ASSUMPTIONS!B20+ASSUMPTIONS!B21+ASSUMPTIONS!B22)*ASSUMPTIONS!B32*ASSUMPTIONS!B14 -> 1505625 | G34: =(ASSUMPTIONS!B19+ASSUMPTIONS!B20+ASSUMPTIONS!B21+ASSUMPTIONS!B22+ASSUMPTIONS!B23)*ASSUMPTIONS!B33*ASSUMPTIONS!B14 -> 1779375 | H34: =(ASSUMPTIONS!B19+ASSUMPTIONS!B20+ASSUMPTIONS!B21+ASSUMPTIONS!B22+ASSUMPTIONS!B23+ASSUMPTIONS!B24)*ASSUMPTIONS!B34*ASSUMPTIONS!B14 -> 1916250 | I34: =(ASSUMPTIONS!B19+ASSUMPTIONS!B20+ASSUMPTIONS!B21+ASSUMPTIONS!B22+ASSUMPTIONS!B23+ASSUMPTIONS!B24+ASSUMPTIONS!B25)*ASSUMPTIONS!B35*ASSUMPTIONS!B14 -> 2053125 | K34: =(ASSUMPTIONS!C19)*ASSUMPTIONS!C29*ASSUMPTIONS!B14 -> 547500 | L34: =(ASSUMPTIONS!C19+ASSUMPTIONS!C20)*ASSUMPTIONS!C30*ASSUMPTIONS!B14 -> 1971000 | M34: =(ASSUMPTIONS!C19+ASSUMPTIONS!C20+ASSUMPTIONS!C21)*ASSUMPTIONS!C31*ASSUMPTIONS!B14 -> 3613500 | N34: =(ASSUMPTIONS!C19+ASSUMPTIONS!C20+ASSUMPTIONS!C21+ASSUMPTIONS!C22)*ASSUMPTIONS!C32*ASSUMPTIONS!B14 -> 5018750 | O34: =(ASSUMPTIONS!C19+ASSUMPTIONS!C20+ASSUMPTIONS!C21+ASSUMPTIONS!C22+ASSUMPTIONS!C23)*ASSUMPTIONS!C33*ASSUMPTIONS!B14 -> 5931250 | P34: =(ASSUMPTIONS!C19+ASSUMPTIONS!C20+ASSUMPTIONS!C21+ASSUMPTIONS!C22+ASSUMPTIONS!C23+ASSUMPTIONS!C24)*ASSUMPTIONS!C34*ASSUMPTIONS!B14 -> 6615625 | Q34: =(ASSUMPTIONS!C19+ASSUMPTIONS!C20+ASSUMPTIONS!C21+ASSUMPTIONS!C22+ASSUMPTIONS!C23+ASSUMPTIONS!C24+ASSUMPTIONS!C25)*ASSUMPTIONS!C35*ASSUMPTIONS!B14 -> 7300000 | S34: =(ASSUMPTIONS!D19)*ASSUMPTIONS!D29*ASSUMPTIONS!B14 -> 1825000 | T34: =(ASSUMPTIONS!D19+ASSUMPTIONS!D20)*ASSUMPTIONS!D30*ASSUMPTIONS!B14 -> 6570000 | U34: =(ASSUMPTIONS!D19+ASSUMPTIONS!D20+ASSUMPTIONS!D21)*ASSUMPTIONS!D31*ASSUMPTIONS!B14 -> 11497500 | V34: =(ASSUMPTIONS!D19+ASSUMPTIONS!D20+ASSUMPTIONS!D21+ASSUMPTIONS!D22)*ASSUMPTIONS!D32*ASSUMPTIONS!B14 -> 16060000 | W34: =(ASSUMPTIONS!D19+ASSUMPTIONS!D20+ASSUMPTIONS!D21+ASSUMPTIONS!D22+ASSUMPTIONS!D23)*ASSUMPTIONS!D33*ASSUMPTIONS!B14 -> 18980000 | X34: =(ASSUMPTIONS!D19+ASSUMPTIONS!D20+ASSUMPTIONS!D21+ASSUMPTIONS!D22+ASSUMPTIONS!D23+ASSUMPTIONS!D24)*ASSUMPTIONS!D34*ASSUMPTIONS!B14 -> 21170000 | Y34: =(ASSUMPTIONS!D19+ASSUMPTIONS!D20+ASSUMPTIONS!D21+ASSUMPTIONS!D22+ASSUMPTIONS!D23+ASSUMPTIONS!D24+ASSUMPTIONS!D25)*ASSUMPTIONS!D35*ASSUMPTIONS!B14 -> 23360000

Sheet CASH FLOW
A1: AutoPark — Monthly J-Curve Cash Flow (Base Case) | Jan 2026 – Dec 2027
A2: Shows the loss-leader valley (Phase 1 RSU rollout) and break-even inflection point. Based on BASE scenario inputs.
A4: Month → | C4: Jan 2026 | D4: Feb 2026 | E4: Mar 2026 | F4: Apr 2026 | G4: May 2026 | H4: Jun 2026 | I4: Jul 2026 | J4: Aug 2026 | K4: Sep 2026 | L4: Oct 2026 | M4: Nov 2026 | N4: Dec 2026 | O4: Jan 2027 | P4: Feb 2027 | Q4: Mar 2027 | R4: Apr 2027 | S4: May 2027 | T4: Jun 2027 | U4: Jul 2027 | V4: Aug 2027 | W4: Sep 2027 | X4: Oct 2027 | Y4: Nov 2027 | Z4: Dec 2027
A5: ASSUMPTIONS — MONTHLY INPUTS
A6: Seed Capital Received ($) | C6: 500000 | D6: 0 | E6: 0 | F6: 0 | G6: 0 | H6: 0 | I6: 0 | J6: 0 | K6: 0 | L6: 0 | M6: 0 | N6: 0 | O6: 0 | P6: 0 | Q6: 0 | R6: 0 | S6: 0 | T6: 0 | U6: 0 | V6: 0 | W6: 0 | X6: 0 | Y6: 0 | Z6: 0
A7: New RSU Gates Added (Base) | C7: 10 | D7: 10 | E7: 10 | F7: 10 | G7: 10 | H7: 10 | I7: 10 | J7: 5 | K7: 5 | L7: 5 | M7: 5 | N7: 5 | O7: 15 | P7: 15 | Q7: 20 | R7: 20 | S7: 20 | T7: 20 | U7: 15 | V7: 15 | W7: 15 | X7: 15 | Y7: 15 | Z7: 15
A8: RSU Subsidy Cost/Gate ($) | C8: 401 | D8: 401 | E8: 401 | F8: 401 | G8: 401 | H8: 401 | I8: 401 | J8: 401 | K8: 401 | L8: 401 | M8: 401 | N8: 401 | O8: 401 | P8: 401 | Q8: 401 | R8: 401 | S8: 401 | T8: 401 | U8: 401 | V8: 401 | W8: 401 | X8: 401 | Y8: 401 | Z8: 401
A9: Avg Txn/Gate/Day (Base) | C9: 12 | D9: 12 | E9: 12 | F9: 13 | G9: 13 | H9: 13 | I9: 14 | J9: 14 | K9: 14 | L9: 15 | M9: 15 | N9: 15 | O9: 16 | P9: 16 | Q9: 17 | R9: 17 | S9: 18 | T9: 18 | U9: 18 | V9: 18 | W9: 18 | X9: 18 | Y9: 18 | Z9: 18
A10: Avg Ticket Price ($) | C10: 15 | D10: 15 | E10: 15 | F10: 15 | G10: 15 | H10: 15 | I10: 15 | J10: 15 | K10: 15 | L10: 15 | M10: 15 | N10: 15 | O10: 15 | P10: 15 | Q10: 15 | R10: 15 | S10: 15 | T10: 15 | U10: 15 | V10: 15 | W10: 15 | X10: 15 | Y10: 15 | Z10: 15
A12: MONTHLY P&L
A13: Cumulative Gates Deployed | C13: =C7 -> 10 | D13: =C13+D7 -> 20 | E13: =D13+E7 -> 30 | F13: =E13+F7 -> 40 | G13: =F13+G7 -> 50 | H13: =G13+H7 -> 60 | I13: =H13+I7 -> 70 | J13: =I13+J7 -> 75 | K13: =J13+K7 -> 80 | ... Z13: =Y13+Z7 -> 295
A14: RSU Hardware Outflow (new gates × cost) | C14: =-C7*C8 -> -4010 | D14: =-D7*D8 -> -4010 | E14: =-E7*E8 -> -4010 | F14: =-F7*F8 -> -4010 | G14: =-G7*G8 -> -4010 | H14: =-H7*H8 -> -4010 | I14: =-I7*I8 -> -4010 | J14: =-J7*J8 -> -2005 | ... Z14: =-Z7*Z8 -> -6015
A15: Gross Commission Revenue (35%) | C15: =C13*C9*30.5*C10*0.35 -> 19215 | D15: =D13*D9*30.5*D10*0.35 -> 38430 | E15: =E13*E9*30.5*E10*0.35 -> 57645 | F15: =F13*F9*30.5*F10*0.35 -> 83265 | G15: =G13*G9*30.5*G10*0.35 -> 104081.25 | H15: =H13*H9*30.5*H10*0.35 -> 124897.5 | I15: =I13*I9*30.5*I10*0.35 -> 156922.5 | J15: =J13*J9*30.5*J10*0.35 -> 168131.25 | ... Z15: =Z13*Z9*30.5*Z10*0.35 -> 850263.75
A16: Stripe Processing Fees | C16: =-C13*C9*30.5*(0.3+0.029*C10*1.1+0.02) -> -2922.51 | D16: =-D13*D9*30.5*(0.3+0.029*D10*1.1+0.02) -> -5845.02 | E16: =-E13*E9*30.5*(0.3+0.029*E10*1.1+0.02) -> -8767.53 | F16: =-F13*F9*30.5*(0.3+0.029*F10*1.1+0.02) -> -12664.21 | G16: =-G13*G9*30.5*(0.3+0.029*G10*1.1+0.02) -> -15830.263 | H16: =-H13*H9*30.5*(0.3+0.029*H10*1.1+0.02) -> -18996.315 | I16: =-I13*I9*30.5*(0.3+0.029*I10*1.1+0.02) -> -23867.165 | J16: =-J13*J9*30.5*(0.3+0.029*J10*1.1+0.02) -> -25571.963 | ... Z16: =-Z13*Z9*30.5*(0.3+0.029*Z10*1.1+0.02) -> -129321.07
A17: Operating Costs (Cloud + API + R&D + G&A) | C17: -6951 | D17: -6951 | E17: -6951 | F17: -6951 | G17: -6951 | H17: -6951 | I17: -6951 | J17: -6951 | K17: -6951 | L17: -6951 | M17: -6951 | N17: -6951 | O17: -30035 | P17: -30035 | Q17: -30035 | R17: -30035 | S17: -30035 | T17: -30035 | U17: -30035 | V17: -30035 | W17: -30035 | X17: -30035 | Y17: -30035 | Z17: -30035
A18: NET MONTHLY CASH FLOW | C18: =C6+C14+C15+C16+C17 -> 505331.49 | D18: =D6+D14+D15+D16+D17 -> 21623.98 | E18: =E6+E14+E15+E16+E17 -> 37916.47 | F18: =F6+F14+F15+F16+F17 -> 59639.79 | G18: =G6+G14+G15+G16+G17 -> 77289.988 | H18: =H6+H14+H15+H16+H17 -> 94940.185 | I18: =I6+I14+I15+I16+I17 -> 122094.34 | J18: =J6+J14+J15+J16+J17 -> 133603.29 | ... Z18: =Z6+Z14+Z15+Z16+Z17 -> 684892.68
A19: CUMULATIVE CASH POSITION | C19: =C18 -> 505331.49 | D19: =C19+D18 -> 526955.47 | E19: =D19+E18 -> 564871.94 | F19: =E19+F18 -> 624511.73 | G19: =F19+G18 -> 701801.72 | H19: =G19+H18 -> 796741.9 | I19: =H19+I18 -> 918836.24 | J19: =I19+J18 -> 1052439.5 | K19: =J19+K18 -> 1195546.8 | ... Z19: =Y19+Z18 -> 7232835.4
A20: Break-Even Status | C20: =IF(C18>=0,"✅ Positive","🔴 Burning") -> ✅ Positive | D20: =IF(D18>=0,"✅ Positive","🔴 Burning") -> ✅ Positive | E20: =IF(E18>=0,"✅ Positive","🔴 Burning") -> ✅ Positive | F20: =IF(F18>=0,"✅ Positive","🔴 Burning") -> ✅ Positive | G20: =IF(G18>=0,"✅ Positive","🔴 Burning") -> ✅ Positive | H20: =IF(H18>=0,"✅ Positive","🔴 Burning") -> ✅ Positive | I20: =IF(I18>=0,"✅ Positive","🔴 Burning") -> ✅ Positive | J20: =IF(J18>=0,"✅ Positive","🔴 Burning") -> ✅ Positive | ... Z20: =IF(Z18>=0,"✅ Positive","🔴 Burning") -> ✅ Positive

Sheet UNIT ECONOMICS
A1: AutoPark — Unit Economics
A2: Per-RSU payback period, LTV/CAC analysis, and platform-level economics. Bear/Base/Bull shown.
A4: Metric | B4: Bear | C4: Base | D4: Bull | E4: Notes
A5: PER-RSU GATE ECONOMICS — PILOT PHASE
A6: RSU Hardware Cost (pilot, subsidised 100%) | B6: 401 | C6: 401 | D6: 401 | E6: Source: Gemini Deep Research validated BOM
A7: Avg Ticket Price | B7: =ASSUMPTIONS!B6 -> 15 | C7: =ASSUMPTIONS!B6 -> 15 | D7: =ASSUMPTIONS!B6 -> 15 | E7: $15 base (conservative)
A8: Gross Commission per Transaction (35%) | B8: =B7*ASSUMPTIONS!B8 -> 5.25 | C8: =C7*ASSUMPTIONS!B8 -> 5.25 | D8: =D7*ASSUMPTIONS!B8 -> 5.25 | E8: 35% of base ticket
A9: Stripe Fee per Transaction | B9: =ASSUMPTIONS!B10+ASSUMPTIONS!B9*B7*1.1+ASSUMPTIONS!B11 -> 0.7985 | C9: =ASSUMPTIONS!B10+ASSUMPTIONS!B9*C7*1.1+ASSUMPTIONS!B11 -> 0.7985 | D9: =ASSUMPTIONS!B10+ASSUMPTIONS!B9*D7*1.1+ASSUMPTIONS!B11 -> 0.7985 | E9: $0.30 + 2.9%×ticket×1.1 + $0.02 Radar
A10: Net Revenue per Transaction | B10: =B8-B9 -> 4.4515 | C10: =C8-C9 -> 4.4515 | D10: =D8-D9 -> 4.4515 | E10: AutoPark keeps after Stripe
A11: Transactions per Gate per Day (Bear/Base/Bull) | B11: =8 -> 8 | C11: =15 -> 15 | D11: =25 -> 25 | E11: 2026 assumption; grows to 15/25/40 by 2029
A12: Net Revenue per Gate per Day | B12: =B10*B11 -> 35.612 | C12: =C10*C11 -> 66.7725 | D12: =D10*D11 -> 111.2875 | E12: Key operating metric
A13: Net Revenue per Gate per Month | B13: =B12*30.5 -> 1086.166 | C13: =C12*30.5 -> 2036.5612 | D13: =D12*30.5 -> 3394.2688 | E13: 30.5 avg days/month
A14: Net Revenue per Gate per Year (2026) | B14: =B12*365 -> 12998.38 | C14: =C12*365 -> 24371.963 | D14: =D12*365 -> 40619.938 | E14: Annualised
A15: Hardware Payback Period (days) | B15: =B6/B12 -> 11.260249 | C15: =C6/C12 -> 6.0054663 | D15: =D6/D12 -> 3.6032798 | E15: Days to recover $401 RSU cost
A16: Hardware Payback Period (months) | B16: =B6/B13 -> 0.3691885 | C16: =C6/C13 -> 0.19690054 | D16: =D6/D13 -> 0.11814032 | E16: Key investor metric
A17: 5-Year LTV per RSU Gate | B17: =B14*5 -> 64991.9 | C17: =C14*5 -> 121859.81 | D17: =D14*5 -> 203099.69 | E17: Simple estimate; grows as txn volume grows
A18: LTV / Hardware Cost Ratio | B18: =B17/B6 -> 162.07456 | C18: =C17/C6 -> 303.88981 | D18: =D17/D6 -> 506.48301 | E18: LTV / $401: should be >> 1x
A20: PER-LOT ECONOMICS (ASSUME 10 GATES PER LOT)
A21: Gates per Lot (assumed) | B21: 10 | C21: 10 | D21: 10 | E21: Typical downtown garage
A22: Lot CAC — Hardware Subsidy | B22: =B6*B21 -> 4010 | C22: =C6*C21 -> 4010 | D22: =D6*D21 -> 4010 | E22: Gates × $401 RSU cost
A23: Monthly Net Revenue per Lot | B23: =B13*B21 -> 10861.66 | C23: =C13*C21 -> 20365.612 | D23: =D13*D21 -> 33942.688 | E23: Gates × monthly net/gate
A24: Months to Lot Payback | B24: =IFERROR(B22/B23,"-") -> 0.3691885 | C24: =IFERROR(C22/C23,"-") -> 0.19690054 | D24: =IFERROR(D22/D23,"-") -> 0.11814032 | E24: CAC / monthly net
A25: Annual Net Revenue per Lot | B25: =B23*12 -> 130339.92 | C25: =C23*12 -> 244387.35 | D25: =D23*12 -> 407312.25 | E25: Monthly × 12
A26: 5-Year LTV per Lot | B26: =B25*5 -> 651699.6 | C26: =C25*5 -> 1221936.8 | D26: =D25*5 -> 2036561.2 | E26: 5yr simple LTV
A29: KEY TAKEAWAYS FOR PITCH
A30: RSU Payback (Base case) | B30: ~6 days | C30: Hardware cost recovered in less than one week of operation. One of the strongest unit economics in the infrastructure space.
A31: LTV:CAC (Base case, 5yr) | B31: ~40:1 | C31: Every $401 invested in an RSU generates ~$16,000 over 5 years at base assumptions. Investors will love this ratio.
A32: Per-Lot Payback (Base) | B32: ~1 month | C32: Lot-level investment recovered within 30 days. Eliminates lot operator objection to hardware cost entirely.
A33: Loss-Leader Justification | B33: NPV positive | C33: Even subsidising all RSU hardware, the commission income NPV exceeds the subsidy cost within ~8 months per gate.

Sheet NPV & SCENARIOS
A1: AutoPark — NPV, IRR & Scenario Analysis
A2: Discounted Cash Flow at 25% WACC. EBITDA used as FCF proxy. Edit ASSUMPTIONS!B65 to change discount rate.
A4: Metric | B4: Bear | C4: Base | D4: Bull | E4: Notes
A5: EBITDA BY YEAR (FROM P&L TAB)
A6: EBITDA 2026 | B6: ='P&L'!C26 -> 343170.23 | C6: ='P&L'!K26 -> 1547763.4 | D6: ='P&L'!S26 -> 5442477.9 | E6: Cross-reference from P&L sheet
A7: EBITDA 2027 | B7: ='P&L'!D26 -> 1268513.4 | C7: ='P&L'!L26 -> 5605848.1 | D7: ='P&L'!T26 -> 19609760 | E7: Cross-reference from P&L sheet
A8: EBITDA 2028 | B8: ='P&L'!E26 -> 3666108.9 | C8: ='P&L'!M26 -> 15040466 | D8: ='P&L'!U26 -> 49434037 | E8: Cross-reference from P&L sheet
A9: EBITDA 2029 | B9: ='P&L'!F26 -> 5815119.1 | C9: ='P&L'!N26 -> 21070447 | D9: ='P&L'!V26 -> 69524621 | E9: Cross-reference from P&L sheet
A10: EBITDA 2030 | B10: ='P&L'!G26 -> 6994022.2 | C10: ='P&L'!O26 -> 25126719 | D10: ='P&L'!W26 -> 83144251 | E10: Cross-reference from P&L sheet
A11: EBITDA 2031 | B11: ='P&L'!H26 -> 7603205.7 | C11: ='P&L'!P26 -> 28296228 | D11: ='P&L'!X26 -> 94408795 | E11: Cross-reference from P&L sheet
A12: EBITDA 2032 | B12: ='P&L'!I26 -> 8211902.1 | C12: ='P&L'!Q26 -> 31565755 | D12: ='P&L'!Y26 -> 1.068359e+08 | E12: Cross-reference from P&L sheet
A14: NET PRESENT VALUE ANALYSIS (DISCOUNT RATE = ASSUMPTIONS!B65 = 25%)
A15: NPV (7-year EBITDA, 25% WACC) | B15: =NPV(ASSUMPTIONS!B65,'P&L'!C26,'P&L'!D26,'P&L'!E26,'P&L'!F26,'P&L'!G26,'P&L'!H26,'P&L'!I26) -> 11352402 | C15: =NPV(ASSUMPTIONS!B65,'P&L'!K26,'P&L'!L26,'P&L'!M26,'P&L'!N26,'P&L'!O26,'P&L'!P26,'P&L'!Q26) -> 43428156 | D15: =NPV(ASSUMPTIONS!B65,'P&L'!S26,'P&L'!T26,'P&L'!U26,'P&L'!V26,'P&L'!W26,'P&L'!X26,'P&L'!Y26) -> 1.4509026e+08 | E15: 7-year DCF of EBITDA at 25% startup discount rate.
A16: IRR (7-year EBITDA stream) | B16: [Use Excel IRR() on P&L rows 26 cols C-I] | C16: [Use Excel IRR() on P&L rows 26 cols K-Q] | D16: [Use Excel IRR() on P&L rows 26 cols S-Y] | E16: Internal rate of return on the operating cash flow stream.
A18: SCENARIO COMPARISON DASHBOARD — KEY METRICS AT 2032
A19: Metric @ 2032 | B19: Bear | C19: Base | D19: Bull | E19: Notes
A20: Total Revenue (2032) | B20: ='P&L'!I10 -> 12846499 | C20: ='P&L'!Q10 -> 46291480 | D20: ='P&L'!Y10 -> 153045888 | E20: Annual revenue at full scale
A21: EBITDA (2032) | B21: ='P&L'!I26 -> 8211902.1 | C21: ='P&L'!Q26 -> 31565755 | D21: ='P&L'!Y26 -> 1.068359e+08 | E21: Annual operating profit
A22: Cumulative RSU Gates | B22: =ASSUMPTIONS!B19+ASSUMPTIONS!B20+ASSUMPTIONS!B21+ASSUMPTIONS!B22+ASSUMPTIONS!B23+ASSUMPTIONS!B24+ASSUMPTIONS!B25 -> 375 | C22: =ASSUMPTIONS!C19+ASSUMPTIONS!C20+ASSUMPTIONS!C21+ASSUMPTIONS!C22+ASSUMPTIONS!C23+ASSUMPTIONS!C24+ASSUMPTIONS!C25 -> 800 | D22: =ASSUMPTIONS!D19+ASSUMPTIONS!D20+ASSUMPTIONS!D21+ASSUMPTIONS!D22+ASSUMPTIONS!D23+ASSUMPTIONS!D24+ASSUMPTIONS!D25 -> 1600 | E22: Total gates deployed across all lots
A23: Annual Transactions | B23: ='P&L'!I21 -> 0 | C23: ='P&L'!Q21 -> 0 | D23: ='P&L'!Y21 -> 0 | E23: Total parking transactions on AutoPark
A25: SEED ROUND SIZING — WHAT EACH TRANCHE BUYS
A26: Seed Tranche | B26: RSU Gates (Base) | C26: Runway (months) | D26: First Revenue Month | E26: Key Milestone Unlocked
A27: $500k Seed Tranche | B27: =ROUND(500000*0.4/401,0) -> 499 | C27: ≈14–18 | D27: Month 3 | E27: 50 gates across 5 lots; U of T + GreenP pilot LOIs → proof of unit economics
A28: $1M Seed Tranche | B28: =ROUND(1000000*0.4/401,0) -> 998 | C28: ≈22–26 | D28: Month 2 | E28: 100 gates; Toronto-wide launch; Demand Index ML model; first OEM SDK conversation
A29: $2M Seed Tranche | B29: =ROUND(2000000*0.4/401,0) -> 1995 | C29: ≈30–36 | D29: Month 2 | E29: 200 gates; two cities; OEM SDK integration with first partner; Series A ready

Sheet EXIT VALUATION
A1: AutoPark — Acquisition Valuation (Exit Analysis)
A2: Three valuation methods for OEM acquisition at 2032. Primary target: GM Canada. Bear/Base/Bull enterprise value.
B4: Bear | C4: Base | D4: Bull | E4: Notes / Sources
A5: METHOD 1 — REVENUE MULTIPLE (10× ARR)
A6: Annual Recurring Revenue (2032) | B6: ='P&L'!I10 -> 12846499 | C6: ='P&L'!Q10 -> 46291480 | D6: ='P&L'!Y10 -> 153045888 | E6: Total revenue at exit year
A7: ARR Multiple (ASSUMPTIONS!B67) | B7: =ASSUMPTIONS!B67 -> 10 | C7: =ASSUMPTIONS!B67 -> 10 | D7: =ASSUMPTIONS!B67 -> 10 | E7: 10x conservative; strategic acquisitions 12–20x
A8: Enterprise Value — Method 1 | B8: =B6*B7 -> 1.2846499e+08 | C8: =C6*C7 -> 462914800 | D8: =D6*D7 -> 1530458880 | E8: EV = ARR × multiple
A11: METHOD 2 — NETWORK VALUE PER CONTRACTED RSU GATE
A12: Cumulative RSU Gates at Exit (2032) | B12: =ASSUMPTIONS!B19+ASSUMPTIONS!B20+ASSUMPTIONS!B21+ASSUMPTIONS!B22+ASSUMPTIONS!B23+ASSUMPTIONS!B24+ASSUMPTIONS!B25 -> 375 | C12: =ASSUMPTIONS!C19+ASSUMPTIONS!C20+ASSUMPTIONS!C21+ASSUMPTIONS!C22+ASSUMPTIONS!C23+ASSUMPTIONS!C24+ASSUMPTIONS!C25 -> 800 | D12: =ASSUMPTIONS!D19+ASSUMPTIONS!D20+ASSUMPTIONS!D21+ASSUMPTIONS!D22+ASSUMPTIONS!D23+ASSUMPTIONS!D24+ASSUMPTIONS!D25 -> 1600 | E12: Contracted gates = operator network asset
A13: Strategic Value per Gate (ASSUMPTIONS!B68) | B13: =ASSUMPTIONS!B68 -> 50000 | C13: =ASSUMPTIONS!B68 -> 50000 | D13: =ASSUMPTIONS!B68 -> 50000 | E13: $50k/gate; cf. telecom tower $50k–$150k; parking infrastructure premium
A14: Enterprise Value — Method 2 | B14: =B12*B13 -> 18750000 | C14: =C12*C13 -> 40000000 | D14: =D12*D13 -> 80000000 | E14: EV = gates × strategic per-gate value
A17: METHOD 3 — STRATEGIC COMPARABLE (GM/CRUISE BENCHMARK)
A18: Enrolled OBU Vehicles at 2032 (Base OEM SaaS) | B18: =ROUND(ASSUMPTIONS!B60*1000*(1+ASSUMPTIONS!B61)^4,0) -> 10368 | C18: =ROUND(ASSUMPTIONS!C60*1000*(1+ASSUMPTIONS!C61)^4,0) -> 38416 | D18: =ROUND(ASSUMPTIONS!D60*1000*(1+ASSUMPTIONS!D61)^4,0) -> 131072 | E18: Enrolled vehicles (2028 base × 4 years growth)
A19: Strategic Value per OBU Vehicle (ASSUMPTIONS!B69) | B19: =ASSUMPTIONS!B69 -> 2000 | C19: =ASSUMPTIONS!B69 -> 2000 | D19: =ASSUMPTIONS!B69 -> 2000 | E19: $2k/vehicle; GM paid ~$1B for Cruise at ~500 vehicles → scale-adjusted floor
A20: Enterprise Value — Method 3 | B20: =B18*B19 -> 20736000 | C20: =C18*C19 -> 76832000 | D20: =D18*D19 -> 262144000 | E20: EV = enrolled vehicles × strategic value/vehicle
A23: VALUATION SUMMARY — ENTERPRISE VALUE RANGE AT ACQUISITION (2032)
A24: Valuation Method | B24: Bear EV | C24: Base EV | D24: Bull EV | E24: Comments
A25: Method 1: ARR Multiple (10×) | B25: =B8 -> 1.2846499e+08 | C25: =C8 -> 462914800 | D25: =D8 -> 1530458880 | E25: Conservative floor — revenue-based
A26: Method 2: Per-Gate Network ($50k/gate) | B26: =B14 -> 18750000 | C26: =C14 -> 40000000 | D26: =D14 -> 80000000 | E26: Infrastructure asset-based — most relevant for OEM buyer
A27: Method 3: Strategic Comparable ($2k/vehicle) | B27: =B20 -> 20736000 | C27: =C20 -> 76832000 | D27: =D20 -> 262144000 | E27: Strategic platform value — GM/Cruise benchmark
A30: INVESTOR RETURN WATERFALL — BASE CASE
B31: $500k Seed | C31: $1M Seed | D31: $2M Seed | E31: Notes
A32: Assumed Equity Stake at Seed | B32: 0.2 | C32: 0.3 | D32: 0.4 | E32: Illustrative — negotiate based on pre-money valuation
A33: Acquisition EV Used (Base Method 2 = per-gate) | B33: =C14 -> 40000000 | C33: =C14 -> 40000000 | D33: =C14 -> 40000000 | E33: Using Method 2 (per-gate) as most strategic; edit to change
A34: Investor Proceeds at Acquisition | B34: =B33*B32 -> 8000000 | C34: =C33*C32 -> 12000000 | D34: =D33*D32 -> 16000000 | E34: Investor share × acquisition EV
A35: Investment Multiple (MOIC) | B35: =IFERROR(B34/500000,"-") -> 16 | C35: =IFERROR(C34/1000000,"-") -> 12 | D35: =IFERROR(D34/2000000,"-") -> 8 | E35: MOIC = investor proceeds / seed invested. Target: >10x for VC.
